Workbook

Sheet Graphs
B2: ="Achieved vs. Possible Module Scores (" & ROUND(AVERAGEIF(Calculator!D40:D45, ">0", Calculator!C40:C45)*100, 0) & "% vs. " & ROUND(AVERAGEIF(Calculator!D40:D45, ">0")*100, 0) & "%, " & ROUND((AVERAGEIF(Calculator!D40:D45, ">0", Calculator!C40:C45)/AVERAGEIF(Calculator!D40:D45, ">0"))*100,0) & "% Average)" -> Achieved vs. Possible Module Scores (57% vs. 89%, 64% Average) | R2: Average Marks Required
R3: Module | S3: 1st | T3: 2:1 | U3: Pass
R4: ADS | S4: =IF(Calculator!F40 > 0, Calculator!F40, "1st Achieved") -> 0.67424242 | T4: {=_xlfn.IFS(S4="1st Achieved", "-", Calculator!G40 > 0, Calculator!G40, TRUE, "2:1 Achieved")} -> 0.52272727 | U4: {=_xlfn.IFS(T4="-", "-", T4="2:1 Achieved", "-", Calculator!H40 > 0, Calculator!H40, TRUE, "Passed")} -> 0.37121212
R5: CT | S5: =IF(Calculator!F41 > 0, Calculator!F41, "1st Achieved") -> 1st Achieved | T5: {=_xlfn.IFS(S5="1st Achieved", "-", Calculator!G41 > 0, Calculator!G41, TRUE, "2:1 Achieved")} -> - | U5: {=_xlfn.IFS(T5="-", "-", T5="2:1 Achieved", "-", Calculator!H41 > 0, Calculator!H41, TRUE, "Passed")} -> -
R6: CS | S6: =IF(Calculator!F42 > 0, Calculator!F42, "1st Achieved") -> 1 | T6: {=_xlfn.IFS(S6="1st Achieved", "-", Calculator!G42 > 0, Calculator!G42, TRUE, "2:1 Achieved")} -> 2:1 Achieved | U6: {=_xlfn.IFS(T6="-", "-", T6="2:1 Achieved", "-", Calculator!H42 > 0, Calculator!H42, TRUE, "Passed")} -> -
R7: DM | S7: =IF(Calculator!F43 > 0, Calculator!F43, "1st Achieved") -> 1 | T7: {=_xlfn.IFS(S7="1st Achieved", "-", Calculator!G43 > 0, Calculator!G43, TRUE, "2:1 Achieved")} -> 1 | U7: {=_xlfn.IFS(T7="-", "-", T7="2:1 Achieved", "-", Calculator!H43 > 0, Calculator!H43, TRUE, "Passed")} -> Passed
R8: MCS | S8: =IF(Calculator!F44 > 0, Calculator!F44, "1st Achieved") -> 1 | T8: {=_xlfn.IFS(S8="1st Achieved", "-", Calculator!G44 > 0, Calculator!G44, TRUE, "2:1 Achieved")} -> 2:1 Achieved | U8: {=_xlfn.IFS(T8="-", "-", T8="2:1 Achieved", "-", Calculator!H44 > 0, Calculator!H44, TRUE, "Passed")} -> -
R9: P(B) | S9: =IF(Calculator!F45 > 0, Calculator!F45, "1st Achieved") -> 1st Achieved | T9: {=_xlfn.IFS(S9="1st Achieved", "-", Calculator!G45 > 0, Calculator!G45, TRUE, "2:1 Achieved")} -> - | U9: {=_xlfn.IFS(T9="-", "-", T9="2:1 Achieved", "-", Calculator!H45 > 0, Calculator!H45, TRUE, "Passed")} -> -
R10: Overall | S10: =IF(Calculator!F46 > 0, Calculator!F46, "1st Achieved") -> 1.1642318 | T10: {=_xlfn.IFS(S10="1st Achieved", "-", Calculator!G46 > 0, Calculator!G46, TRUE, "2:1 Achieved")} -> 0.25514085 | U10: {=_xlfn.IFS(T10="-", "-", T10="2:1 Achieved", "-", Calculator!H46 > 0, Calculator!H46, TRUE, "Passed")} -> Passed
B15: =COUNTIF('Attendence Tracker'!$F$2:$AI$1001, "Attended") & " classes attended this academic year (" & COUNTA('Attendence Tracker'!$F$2:$AI$1001) & " possible, " & COUNTIF('Attendence Tracker'!$F$2:$AI$1001, "Missed") & " to catch up on, " & ROUND(Calculator!$AG$27,3)*100 & "% average attendence)." -> 99 classes attended this academic year (287 possible, 15 to catch up on, 34.5% average attendence).
C17: Week 1 | G17: Week 5 | L17: Week 10 | Q17: Week 15 | V17: Week 20 | AA17: Week 25 | AF17: Week 30
B18: Mon | C18: =Calculator!C22 -> 0 | D18: =Calculator!D22 -> 1 | E18: =Calculator!E22 -> 0.5 | F18: =Calculator!F22 -> 0 | G18: =Calculator!G22 -> 0.5 | H18: =Calculator!H22 -> 0.5 | I18: =Calculator!I22 -> 0.75 | J18: =Calculator!J22 -> 0 | ... AF18: =Calculator!AF22 -> 0
C19: =Calculator!C23 -> 0 | D19: =Calculator!D23 -> 1 | E19: =Calculator!E23 -> 0.33333333 | F19: =Calculator!F23 -> 0 | G19: =Calculator!G23 -> 0.66666667 | H19: =Calculator!H23 -> 0.33333333 | I19: =Calculator!I23 -> 0.33333333 | J19: =Calculator!J23 -> 0.33333333 | ... AF19: =Calculator!AF23 -> 0
B20: Wed | C20: =Calculator!C24 -> 0 | D20: =Calculator!D24 -> 0 | E20: =Calculator!E24 -> 0 | F20: =Calculator!F24 -> 0.5 | G20: =Calculator!G24 -> 0 | H20: =Calculator!H24 -> 0 | I20: =Calculator!I24 -> 0 | J20: =Calculator!J24 -> 0 | ... AF20: =Calculator!AF24 -> 0
C21: =Calculator!C25 -> 0.66666667 | D21: =Calculator!D25 -> 0.75 | E21: =Calculator!E25 -> 0.25 | F21: =Calculator!F25 -> 0.25 | G21: =Calculator!G25 -> 0.25 | H21: =Calculator!H25 -> 0.75 | I21: =Calculator!I25 -> 0 | J21: =Calculator!J25 -> 0.25 | ... AF21: =Calculator!AF25 -> 0
B22: Fri | C22: =Calculator!C26 -> 0 | D22: =Calculator!D26 -> 0.33333333 | E22: =Calculator!E26 -> 0 | F22: =Calculator!F26 -> 1 | G22: =Calculator!G26 -> 0.66666667 | H22: =Calculator!H26 -> 0.5 | I22: =Calculator!I26 -> 0 | J22: =Calculator!J26 -> 0.5 | ... AF22: =Calculator!AF26 -> 0
B25: =SUM(Calculator!L31:L36) & " summatives completed this academic year. (Average: " & ROUND(AVERAGEIF(Calculator!P31:P36, ">0"),2)*100 & "%)" -> 17 summatives completed this academic year. (Average: 73%) | J25: =SUM(Calculator!D31:D36) & " formatives completed this academic year. (Average: " & ROUND(AVERAGEIF(Calculator!H31:H36, ">0"),2)*100 & "%)" -> 27 formatives completed this academic year. (Average: 80%)

Sheet Attendence Tracker
A1: Day | B1: Time | C1: Module Code | D1: Module Name | E1: Class Type | F1: Week 1 | G1: Week 2 | H1: Week 3 | I1: Week 4 | J1: Week 5 | K1: Week 6 | L1: Week 7 | M1: Week 8 | N1: Week 9 | O1: Week 10 | P1: Week 11 | Q1: Week 12 | R1: Week 13 | S1: Week 14 | T1: Week 15 | U1: Week 16 | V1: Week 17 | W1: Week 18 | X1: Week 19 | Y1: Week 20 | Z1: Week 21 | AA1: Week 22 | AB1: Week 23 | AC1: Week 24 | AD1: Week 25 | AE1: Week 26 | AF1: Week 27 | AG1: Week 28 | AH1: Week 29 | AI1: Week 30
A2: Monday | B2: 0.45833333 | C2: COMP1101 | D2: Programming (Black) | E2: Practical | G2: Attended | H2: Attended | I2: Work Done | J2: Attended | K2: Attended | L2: Attended | M2: Work Done | N2: Attended | O2: Attended
A3: Monday | B3: 0.58333333 | C3: COMP1081 | D3: Algorithms and Data Structures | E3: Practical | G3: Attended | H3: Attended | I3: Work Done | J3: Attended | K3: Attended | L3: Attended | M3: Work Done | N3: Attended | O3: Attended
A4: Monday | B4: 0.66666667 | C4: COMP1021 | D4: Mathematics for Computer Science | E4: Lecture | F4: Work Done | G4: Attended | H4: Work Done | I4: Work Done | J4: Work Done | K4: Work Done | L4: Attended | M4: Work Done | N4: Work Done | O4: Work Done
A5: Monday | B5: 0.70833333 | C5: COMP1081 | D5: Algorithms and Data Structures | E5: Lecture | F5: Work Done | G5: Attended | H5: Work Done | I5: Work Done | J5: Work Done | K5: Work Done | L5: Work Done | M5: Work Done | N5: Work Done | O5: Work Done
A6: Tuesday | B6: 0.45833333 | C6: COMP1051 | D6: Computational Thinking | E6: Practical | G6: Attended | H6: Attended | I6: Work Done | J6: Attended | K6: Attended | L6: Attended | M6: Attended | N6: Attended | O6: Work Done
A7: Tuesday | B7: 0.54166667 | C7: COMP1071 | D7: Computer Systems | E7: Lecture | F7: Work Done | G7: Attended | H7: Work Done | I7: Work Done | J7: Attended | K7: Work Done | L7: Work Done | M7: Work Done | N7: Work Done | O7: Work Done
A8: Tuesday | B8: 0.625 | C8: MATH1031 | D8: Discrete Mathematics | E8: Lecture | F8: Work Done | G8: Attended | H8: Work Done | I8: Work Done | J8: Work Done | K8: Work Done | L8: Work Done | M8: Work Done | N8: Work Done | O8: Work Done
A9: Wednesday | B9: 0.375 | C9: COMP1021 | D9: Mathematics for Computer Science | E9: Lecture | F9: Work Done | G9: Work Done | H9: Work Done | I9: Attended | J9: Work Done | K9: Work Done | M9: Work Done | N9: Work Done | O9: Work Done
A10: Wednesday | B10: 0.45833333 | C10: COMP1051 | D10: Computational Thinking | E10: Lecture | F10: Work Done | G10: Work Done | H10: Work Done | I10: Work Done | J10: Work Done | K10: Work Done | L10: Work Done | M10: Work Done | N10: Work Done | O10: Work Done
A11: Thursday | B11: 0.45833333 | C11: COMP1021 | D11: Mathematics for Computer Science | E11: Practical | G11: Attended | H11: Attended | I11: Attended | J11: Attended | K11: Attended | L11: Work Done | M11: Attended | N11: Work Done | O11: Attended
A12: Thursday | B12: 0.58333333 | C12: COMP1081 | D12: Algorithms and Data Structures | E12: Lecture | F12: Attended | G12: Attended | H12: Work Done | I12: Work Done | J12: Work Done | K12: Attended | L12: Work Done | M12: Work Done | N12: Work Done | O12: Work Done
A13: Thursday | B13: 0.625 | C13: MATH1031 | D13: Discrete Mathematics | E13: Lecture | F13: Work Done | G13: Work Done | H13: Work Done | I13: Work Done | J13: Work Done | K13: Work Done | L13: Work Done | M13: Work Done | N13: Work Done | O13: Work Done
A14: Thursday | B14: 0.66666667 | C14: COMP1101 | D14: Programming (Black) | E14: Lecture | F14: Attended | G14: Attended | H14: Work Done | I14: Work Done | J14: Work Done | K14: Attended | L14: Work Done | M14: Work Done | N14: Work Done | O14: Work Done
A15: Friday | B15: 0.375 | C15: COMP1101 | D15: Programming (Black) | E15: Lecture | F15: Work Done | G15: Work Done | H15: Work Done | I15: Attended | L15: Work Done | N15: Work Done | O15: Work Done
A16: Friday | B16: 0.45833333 | C16: COMP1071 | D16: Computer Systems | E16: Practical | G16: Attended | H16: Work Done | I16: Attended | J16: Attended | K16: Attended | L16: Work Done | M16: Attended | N16: Attended | O16: Attended
A17: Friday | B17: 0.58333333 | C17: MATH1031 | D17: Discrete Mathematics | E17: Tutorial | H17: Work Done | J17: Attended | L17: Work Done | N17: Attended
A18: Friday | B18: 0.66666667 | C18: COMP1071 | D18: Computer Systems | E18: Lecture | F18: Work Done | G18: Work Done | H18: Work Done | I18: Attended | J18: Work Done | K18: Work Done | L18: Work Done | M18: Work Done | N18: Work Done | O18: Work Done
A19: Monday | B19: 0.58333333 | C19: COMP1081 | D19: Algorithms and Data Structures | E19: Practical | P19: Attended | Q19: Attended | R19: Attended | S19: Attended | T19: Attended | U19: Work Done | V19: Attended | W19: Attended | X19: Attended | Y19: Work Done
A20: Monday | B20: 0.66666667 | C20: COMP1021 | D20: Mathematics for Computer Science | E20: Lecture | P20: Attended | Q20: Attended | R20: Work Done | S20: Attended | T20: Work Done | U20: Work Done | V20: Work Done | W20: Work Done | X20: Work Done | Y20: Missed
A21: Monday | B21: 0.70833333 | C21: COMP1081 | D21: Algorithms and Data Structures | E21: Lecture | P21: Attended | Q21: Work Done | R21: Work Done | S21: Work Done | T21: Work Done | U21: Work Done | V21: Work Done | W21: Work Done | X21: Work Done | Y21: Missed
A22: Tuesday | B22: 0.45833333 | C22: COMP1051 | D22: Computational Thinking | E22: Practical | P22: Attended | Q22: Attended | R22: Attended | S22: Attended | T22: Attended | U22: Work Done | V22: Attended | W22: Attended | X22: Attended | Y22: Attended
A23: Tuesday | B23: 0.54166667 | C23: COMP1071 | D23: Computer Systems | E23: Lecture | P23: Attended | Q23: Attended | R23: Work Done | S23: Attended | T23: Work Done | U23: Missed | V23: Missed | W23: Missed | X23: Missed | Y23: Missed
A24: Tuesday | B24: 0.625 | C24: MATH1031 | D24: Discrete Mathematics | E24: Lecture | P24: Attended | Q24: Work Done | R24: Work Done
A25: Wednesday | B25: 0.375 | C25: COMP1021 | D25: Mathematics for Computer Science | E25: Lecture | P25: Work Done | Q25: Work Done | R25: Work Done | S25: Work Done | T25: Work Done | U25: Work Done | V25: Work Done | W25: Work Done | X25: Work Done | Y25: Missed
A26: Wednesday | B26: 0.45833333 | C26: COMP1051 | D26: Computational Thinking | E26: Lecture | P26: Work Done | Q26: Work Done | R26: Work Done | S26: Work Done | T26: Work Done | U26: Work Done | V26: Work Done | W26: Work Done | X26: Work Done
A27: Wednesday | C27: OTHER | D27: Other | Q27: Attended | X27: Attended
A28: Thursday | B28: 0.45833333 | C28: COMP1021 | D28: Mathematics for Computer Science | E28: Practical | P28: Attended | Q28: Work Done | R28: Attended | S28: Attended | T28: Work Done | U28: Work Done | V28: Attended | W28: Attended | X28: Attended | Y28: Attended
A29: Thursday | B29: 0.58333333 | C29: COMP1081 | D29: Algorithms and Data Structures | E29: Lecture | P29: Attended | Q29: Work Done | R29: Work Done | S29: Attended | T29: Work Done | U29: Work Done | V29: Work Done | W29: Work Done | X29: Missed | Y29: Missed
A30: Thursday | B30: 0.625 | C30: MATH1031 | D30: Discrete Mathematics | E30: Lecture | P30: Attended | Q30: Work Done | R30: Work Done
A31: Thursday | B31: 0.66666667 | C31: COMP1051 | D31: Computational Thinking | E31: Lecture | Q31: Work Done | R31: Work Done | S31: Work Done | T31: Work Done | U31: Work Done | V31: Work Done | W31: Work Done | X31: Work Done
A32: Friday | B32: 0.375 | C32: COMP1101 | D32: Programming (Black) | E32: Drop-In
A33: Friday | B33: 0.45833333 | C33: COMP1071 | D33: Computer Systems | E33: Practical | Q33: Work Done | R33: Work Done | S33: Attended | T33: Work Done | U33: Attended | V33: Attended | W33: Work Done | X33: Work Done | Y33: Work Done
A34: Friday | B34: 0.58333333 | C34: MATH1031 | D34: Discrete Mathematics | E34: Tutorial | Q34: Work Done | R34: Work Done
A35: Friday | B35: 0.58333333 | C35: MATH1031 | D35: Discrete Mathematics | E35: Seminar | S35: Attended | T35: Attended | U35: Attended | V35: Attended | W35: Attended | X35: Attended
A36: Friday | B36: 0.66666667 | C36: COMP1071 | D36: Computer Systems | E36: Lecture | P36: Work Done | Q36: Work Done | R36: Work Done | S36: Attended | T36: Work Done | U36: Missed | V36: Missed | W36: Missed | X36: Missed | Y36: Missed

Sheet Formatives Tracker
A1: Status | B1: Release Date | C1: Due Date | D1: Module Code | E1: Module Name | F1: Assignment Name | G1: Assignment Type | H1: Done? | I1: Score | J1: Mark
A2: {=_xlfn.IFS(H2, "Done", B2 > NOW(), "Not Released", C2 < NOW(), "Overdue", TRUE, ROUND(C2 - NOW(), 1) & " Days")} -> Done | B2: 45996 | C2: 46101 | D2: MATH1031 | E2: Discrete Mathematics | F2: E-Assessment 1 - PS5 | G2: Homework | H2: TRUE | J2: {=_xlfn.IFS(H2 = FALSE, "", G2 = "Homework", "", I2 > 0, I2, TRUE, "")}
A3: {=_xlfn.IFS(H3, "Done", B3 > NOW(), "Not Released", C3 < NOW(), "Overdue", TRUE, ROUND(C3 - NOW(), 1) & " Days")} -> Done | B3: 46092 | C3: 46094 | D3: COMP1021 | E3: Mathematics for Computer Science | F3: Formative Assignment 15 | G3: Exam | H3: TRUE | I3: 1 | J3: {=_xlfn.IFS(H3 = FALSE, "", G3 = "Homework", "", I3 > 0, I3, TRUE, "")} -> 1
A4: {=_xlfn.IFS(H4, "Done", B4 > NOW(), "Not Released", C4 < NOW(), "Overdue", TRUE, ROUND(C4 - NOW(), 1) & " Days")} -> Done | B4: 46085 | C4: 46087 | D4: COMP1021 | E4: Mathematics for Computer Science | F4: Formative Assignment 14 | G4: Exam | H4: TRUE | I4: 1 | J4: {=_xlfn.IFS(H4 = FALSE, "", G4 = "Homework", "", I4 > 0, I4, TRUE, "")} -> 1
A5: {=_xlfn.IFS(H5, "Done", B5 > NOW(), "Not Released", C5 < NOW(), "Overdue", TRUE, ROUND(C5 - NOW(), 1) & " Days")} -> Done | B5: 46078 | C5: 46080 | D5: COMP1021 | E5: Mathematics for Computer Science | F5: Formative Assignment 13 | G5: Exam | H5: TRUE | I5: =2/6 -> 0.33333333 | J5: {=_xlfn.IFS(H5 = FALSE, "", G5 = "Homework", "", I5 > 0, I5, TRUE, "")} -> 0.33333333
A6: {=_xlfn.IFS(H6, "Done", B6 > NOW(), "Not Released", C6 < NOW(), "Overdue", TRUE, ROUND(C6 - NOW(), 1) & " Days")} -> Done | B6: 46069 | C6: 46080 | D6: MATH1031 | E6: Discrete Mathematics | F6: Seminar Writing Assignment | G6: Homework | H6: TRUE | I6: 1 | J6: {=_xlfn.IFS(H6 = FALSE, "", G6 = "Homework", "", I6 > 0, I6, TRUE, "")}
A7: {=_xlfn.IFS(H7, "Done", B7 > NOW(), "Not Released", C7 < NOW(), "Overdue", TRUE, ROUND(C7 - NOW(), 1) & " Days")} -> Done | B7: 46071 | C7: 46073 | D7: COMP1021 | E7: Mathematics for Computer Science | F7: Formative Assignment 12 | G7: Exam | H7: TRUE | I7: =7.66/8 -> 0.9575 | J7: {=_xlfn.IFS(H7 = FALSE, "", G7 = "Homework", "", I7 > 0, I7, TRUE, "")} -> 0.9575
A8: {=_xlfn.IFS(H8, "Done", B8 > NOW(), "Not Released", C8 < NOW(), "Overdue", TRUE, ROUND(C8 - NOW(), 1) & " Days")} -> Done | B8: 46064 | C8: 46066 | D8: COMP1021 | E8: Mathematics for Computer Science | F8: Formative Assignment 11 | G8: Exam | H8: TRUE | I8: =4/6 -> 0.66666667 | J8: {=_xlfn.IFS(H8 = FALSE, "", G8 = "Homework", "", I8 > 0, I8, TRUE, "")} -> 0.66666667
A9: {=_xlfn.IFS(H9, "Done", B9 > NOW(), "Not Released", C9 < NOW(), "Overdue", TRUE, ROUND(C9 - NOW(), 1) & " Days")} -> Done | B9: 46057 | C9: 46059 | D9: COMP1021 | E9: Mathematics for Computer Science | F9: Formative Assignment 10 | G9: Exam | H9: TRUE | I9: =7/8 -> 0.875 | J9: {=_xlfn.IFS(H9 = FALSE, "", G9 = "Homework", "", I9 > 0, I9, TRUE, "")} -> 0.875
A10: {=_xlfn.IFS(H10, "Done", B10 > NOW(), "Not Released", C10 < NOW(), "Overdue", TRUE, ROUND(C10 - NOW(), 1) & " Days")} -> Done | B10: 46050 | C10: 46052 | D10: COMP1021 | E10: Mathematics for Computer Science | F10: Formative Assignment 9 | G10: Exam | H10: TRUE | I10: =5/6 -> 0.83333333 | J10: {=_xlfn.IFS(H10 = FALSE, "", G10 = "Homework", "", I10 > 0, I10, TRUE, "")} -> 0.83333333
A11: {=_xlfn.IFS(H11, "Done", B11 > NOW(), "Not Released", C11 < NOW(), "Overdue", TRUE, ROUND(C11 - NOW(), 1) & " Days")} -> Done | B11: 46040 | C11: 46048 | D11: MATH1031 | E11: Discrete Mathematics | F11: Written Assignment 5 | G11: Coursework | H11: TRUE | I11: 1 | J11: {=_xlfn.IFS(H11 = FALSE, "", G11 = "Homework", "", I11 > 0, I11, TRUE, "")} -> 1
A12: {=_xlfn.IFS(H12, "Done", B12 > NOW(), "Not Released", C12 < NOW(), "Overdue", TRUE, ROUND(C12 - NOW(), 1) & " Days")} -> Done | B12: 46043 | C12: 46045 | D12: COMP1021 | E12: Mathematics for Computer Science | F12: Formative Assignment 8 | G12: Exam | H12: TRUE | I12: =6/7 -> 0.85714286
A13: {=_xlfn.IFS(H13, "Done", B13 > NOW(), "Not Released", C13 < NOW(), "Overdue", TRUE, ROUND(C13 - NOW(), 1) & " Days")} -> Done | B13: 46033 | C13: 46036 | D13: MATH1031 | E13: Discrete Mathematics | F13: Collection Exam | G13: Exam | H13: TRUE | I13: 0.51 | J13: {=_xlfn.IFS(H13 = FALSE, "", G13 = "Homework", "", I13 > 0, I13, TRUE, "")} -> 0.51
A14: {=_xlfn.IFS(H14, "Done", B14 > NOW(), "Not Released", C14 < NOW(), "Overdue", TRUE, ROUND(C14 - NOW(), 1) & " Days")} -> Done | B14: 46002 | C14: 46003 | D14: COMP1021 | E14: Mathematics for Computer Science | F14: Formative Assignment 7 | G14: Exam | H14: TRUE | I14: 0.83333333 | J14: {=_xlfn.IFS(H14 = FALSE, "", G14 = "Homework", "", I14 > 0, I14, TRUE, "")} -> 0.83333333
A15: {=_xlfn.IFS(H15, "Done", B15 > NOW(), "Not Released", C15 < NOW(), "Overdue", TRUE, ROUND(C15 - NOW(), 1) & " Days")} -> Done | B15: 45989 | C15: 45999 | D15: MATH1031 | E15: Discrete Mathematics | F15: Written Assignment 4 | G15: Coursework | H15: TRUE | I15: 0.9 | J15: {=_xlfn.IFS(H15 = FALSE, "", G15 = "Homework", "", I15 > 0, I15, TRUE, "")} -> 0.9
A16: {=_xlfn.IFS(H16, "Done", B16 > NOW(), "Not Released", C16 < NOW(), "Overdue", TRUE, ROUND(C16 - NOW(), 1) & " Days")} -> Done | B16: 45995 | C16: 45996 | D16: COMP1021 | E16: Mathematics for Computer Science | F16: Formative Assignment 6 | G16: Exam | H16: TRUE | I16: 1 | J16: {=_xlfn.IFS(H16 = FALSE, "", G16 = "Homework", "", I16 > 0, I16, TRUE, "")} -> 1
A17: {=_xlfn.IFS(H17, "Done", B17 > NOW(), "Not Released", C17 < NOW(), "Overdue", TRUE, ROUND(C17 - NOW(), 1) & " Days")} -> Done | B17: 45982 | C17: 45992 | D17: MATH1031 | E17: Discrete Mathematics | F17: E-Assessment 1 - PS4 | G17: Homework | H17: TRUE | I17: 1 | J17: {=_xlfn.IFS(H17 = FALSE, "", G17 = "Homework", "", I17 > 0, I17, TRUE, "")}
A18: {=_xlfn.IFS(H18, "Done", B18 > NOW(), "Not Released", C18 < NOW(), "Overdue", TRUE, ROUND(C18 - NOW(), 1) & " Days")} -> Done | B18: 45988 | C18: 45989 | D18: COMP1021 | E18: Mathematics for Computer Science | F18: Formative Assignment 5 | G18: Exam | H18: TRUE | I18: 0.875 | J18: {=_xlfn.IFS(H18 = FALSE, "", G18 = "Homework", "", I18 > 0, I18, TRUE, "")} -> 0.875
A19: {=_xlfn.IFS(H19, "Done", B19 > NOW(), "Not Released", C19 < NOW(), "Overdue", TRUE, ROUND(C19 - NOW(), 1) & " Days")} -> Done | B19: 45978 | C19: 45985 | D19: MATH1031 | E19: Discrete Mathematics | F19: Written Assignment 3 | G19: Coursework | H19: TRUE | I19: 0.8 | J19: {=_xlfn.IFS(H19 = FALSE, "", G19 = "Homework", "", I19 > 0, I19, TRUE, "")} -> 0.8
A20: {=_xlfn.IFS(H20, "Done", B20 > NOW(), "Not Released", C20 < NOW(), "Overdue", TRUE, ROUND(C20 - NOW(), 1) & " Days")} -> Done | B20: 45981 | C20: 45982 | D20: COMP1021 | E20: Mathematics for Computer Science | F20: Formative Assignment 4 | G20: Exam | H20: TRUE | I20: 0.71428571 | J20: {=_xlfn.IFS(H20 = FALSE, "", G20 = "Homework", "", I20 > 0, I20, TRUE, "")} -> 0.71428571
A21: {=_xlfn.IFS(H21, "Done", B21 > NOW(), "Not Released", C21 < NOW(), "Overdue", TRUE, ROUND(C21 - NOW(), 1) & " Days")} -> Done | B21: 45971 | C21: 45978 | D21: MATH1031 | E21: Discrete Mathematics | F21: E-Assessment 1 - PS3 | G21: Homework | H21: TRUE | I21: 1 | J21: {=_xlfn.IFS(H21 = FALSE, "", G21 = "Homework", "", I21 > 0, I21, TRUE, "")}
A22: {=_xlfn.IFS(H22, "Done", B22 > NOW(), "Not Released", C22 < NOW(), "Overdue", TRUE, ROUND(C22 - NOW(), 1) & " Days")} -> Done | B22: 45973 | C22: 45975 | D22: COMP1021 | E22: Mathematics for Computer Science | F22: Formative Assignment 3 | G22: Exam | H22: TRUE | I22: 1 | J22: {=_xlfn.IFS(H22 = FALSE, "", G22 = "Homework", "", I22 > 0, I22, TRUE, "")} -> 1
A23: {=_xlfn.IFS(H23, "Done", B23 > NOW(), "Not Released", C23 < NOW(), "Overdue", TRUE, ROUND(C23 - NOW(), 1) & " Days")} -> Done | B23: 45961 | C23: 45971 | D23: MATH1031 | E23: Discrete Mathematics | F23: Written Assignment 2 | G23: Coursework | H23: TRUE | I23: 0.6 | J23: {=_xlfn.IFS(H23 = FALSE, "", G23 = "Homework", "", I23 > 0, I23, TRUE, "")} -> 0.6
A24: {=_xlfn.IFS(H24, "Done", B24 > NOW(), "Not Released", C24 < NOW(), "Overdue", TRUE, ROUND(C24 - NOW(), 1) & " Days")} -> Done | B24: 45966 | C24: 45968 | D24: COMP1021 | E24: Mathematics for Computer Science | F24: Formative Assignment 2 | G24: Exam | H24: TRUE | I24: 0.63 | J24: {=_xlfn.IFS(H24 = FALSE, "", G24 = "Homework", "", I24 > 0, I24, TRUE, "")} -> 0.63
... A28: {=_xlfn.IFS(H28, "Done", B28 > NOW(), "Not Released", C28 < NOW(), "Overdue", TRUE, ROUND(C28 - NOW(), 1) & " Days")} -> Done | B28: 45936 | C28: 45950 | D28: MATH1031 | E28: Discrete Mathematics | F28: E-Assessment 1 - PS1 | G28: Homework | H28: TRUE | I28: 1 | J28: {=_xlfn.IFS(H28 = FALSE, "", G28 = "Homework", "", I28 > 0, I28, TRUE, "")}

Sheet Summatives Tracker
A1: Status | B1: Release Date | C1: Due Date | D1: Module Code | E1: Module Name | F1: Assignment Name | G1: Assignment Type | H1: Done? | I1: Score | J1: Weighting | K1: Weighted Score
A2: {=_xlfn.IFS(H2, "Done", B2 > NOW(), "Not Released", C2 < NOW(), "Overdue", TRUE, ROUND(C2 - NOW(), 1) & " Days")} -> Done | B2: 46093 | C2: 46168 | D2: MATH1032 | E2: Discrete Mathematics | F2: Final Exam | G2: Exam | H2: TRUE | I2: 0.55 | J2: 0.7 | K2: =J2*I2 -> 0.385
A3: {=_xlfn.IFS(H3, "Done", B3 > NOW(), "Not Released", C3 < NOW(), "Overdue", TRUE, ROUND(C3 - NOW(), 1) & " Days")} -> Done | B3: 46093 | C3: 46163 | D3: COMP1021 | E3: Mathematics for Computer Science | F3: Final Exam | G3: Exam | H3: TRUE | I3: 0.54 | J3: 0.66 | K3: =J3*I3 -> 0.3564
A4: {=_xlfn.IFS(H4, "Done", B4 > NOW(), "Not Released", C4 < NOW(), "Overdue", TRUE, ROUND(C4 - NOW(), 1) & " Days")} -> Done | B4: 46093 | C4: 46157 | D4: COMP1071 | E4: Computer Systems | F4: Final Exam | G4: Exam | H4: TRUE | I4: 0.485 | J4: 0.66 | K4: =J4*I4 -> 0.3201
A5: {=_xlfn.IFS(H5, "Done", B5 > NOW(), "Not Released", C5 < NOW(), "Overdue", TRUE, ROUND(C5 - NOW(), 1) & " Days")} -> Done | B5: 46093 | C5: 46155 | D5: COMP1081 | E5: Algorithms and Data Structures | F5: Final Exam | G5: Exam | H5: TRUE | J5: 0.66 | K5: =J5*I5 -> 0
A6: {=_xlfn.IFS(H6, "Done", B6 > NOW(), "Not Released", C6 < NOW(), "Overdue", TRUE, ROUND(C6 - NOW(), 1) & " Days")} -> Done | B6: 46059 | C6: 46142 | D6: COMP1101 | E6: Programming (Black) | F6: Collaborative Project | G6: Coursework | H6: TRUE | I6: 0.71 | J6: 0.5 | K6: =J6*I6 -> 0.355
A7: {=_xlfn.IFS(H7, "Done", B7 > NOW(), "Not Released", C7 < NOW(), "Overdue", TRUE, ROUND(C7 - NOW(), 1) & " Days")} -> Done | B7: 46066 | C7: 46105 | D7: COMP1051 | E7: Computational Thinking | F7: Logic Coursework | G7: Coursework | H7: TRUE | I7: =(72-48)/(100-66) -> 0.70588235 | J7: =40/300 -> 0.13333333 | K7: =J7*I7 -> 0.094117647
A8: {=_xlfn.IFS(H8, "Done", B8 > NOW(), "Not Released", C8 < NOW(), "Overdue", TRUE, ROUND(C8 - NOW(), 1) & " Days")} -> Done | B8: 46059 | C8: 46101 | D8: MATH1032 | E8: Discrete Mathematics | F8: Seminar Report | G8: Coursework | H8: TRUE | I8: 0.55 | J8: 0.2 | K8: =J8*I8 -> 0.11
A9: {=_xlfn.IFS(H9, "Done", B9 > NOW(), "Not Released", C9 < NOW(), "Overdue", TRUE, ROUND(C9 - NOW(), 1) & " Days")} -> Done | B9: 46091 | C9: 46098 | D9: COMP1051 | E9: Computational Thinking | F9: Logic Benchtest | G9: Exam | H9: TRUE | I9: =48/66 -> 0.72727273 | J9: =40/150 -> 0.26666667 | K9: =J9*I9 -> 0.19393939
A10: {=_xlfn.IFS(H10, "Done", B10 > NOW(), "Not Released", C10 < NOW(), "Overdue", TRUE, ROUND(C10 - NOW(), 1) & " Days")} -> Done | B10: 46059 | C10: 46092 | D10: MATH1032 | E10: Discrete Mathematics | F10: Seminar Presentation | G10: Coursework | H10: TRUE | I10: 0.55 | J10: 0.1 | K10: =J10*I10 -> 0.055
A11: {=_xlfn.IFS(H11, "Done", B11 > NOW(), "Not Released", C11 < NOW(), "Overdue", TRUE, ROUND(C11 - NOW(), 1) & " Days")} -> Done | B11: 46059 | C11: 46072 | D11: COMP1101 | E11: Programming (Black) | F11: Web Development Peer Evaluation | G11: Coursework | H11: TRUE | I11: 1 | J11: 0.05 | K11: =J11*I11 -> 0.05
A12: {=_xlfn.IFS(H12, "Done", B12 > NOW(), "Not Released", C12 < NOW(), "Overdue", TRUE, ROUND(C12 - NOW(), 1) & " Days")} -> Done | B12: 45967 | C12: 46051 | D12: COMP1101 | E12: Programming (Black) | F12: Web Development Video | G12: Coursework | H12: TRUE | I12: 0.67 | J12: 0.45 | K12: =J12*I12 -> 0.3015
A13: {=_xlfn.IFS(H13, "Done", B13 > NOW(), "Not Released", C13 < NOW(), "Overdue", TRUE, ROUND(C13 - NOW(), 1) & " Days")} -> Done | B13: 46033 | C13: 46038 | D13: COMP1021 | E13: Mathematics for Computer Science | F13: MCS Benchtest | G13: Exam | H13: TRUE | I13: 0.725 | J13: 0.34 | K13: =J13*I13 -> 0.2465
A14: {=_xlfn.IFS(H14, "Done", B14 > NOW(), "Not Released", C14 < NOW(), "Overdue", TRUE, ROUND(C14 - NOW(), 1) & " Days")} -> Done | B14: 46033 | C14: 46035 | D14: COMP1051 | E14: Computational Thinking | F14: CT Benchtest | G14: Exam | H14: TRUE | I14: 0.66 | J14: 0.4 | K14: =J14*I14 -> 0.264
A15: {=_xlfn.IFS(H15, "Done", B15 > NOW(), "Not Released", C15 < NOW(), "Overdue", TRUE, ROUND(C15 - NOW(), 1) & " Days")} -> Done | B15: 45961 | C15: 46009 | D15: COMP1081 | E15: Algorithms and Data Structures | F15: ADS Coursework | G15: Coursework | H15: TRUE | I15: 0.75 | J15: 0.34 | K15: =J15*I15 -> 0.255
A16: {=_xlfn.IFS(H16, "Done", B16 > NOW(), "Not Released", C16 < NOW(), "Overdue", TRUE, ROUND(C16 - NOW(), 1) & " Days")} -> Done | B16: 45960 | C16: 46003 | D16: COMP1051 | E16: Computational Thinking | F16: Guest Lecture Presentation Video | G16: Coursework | H16: TRUE | I16: 0.81 | J16: 0.2 | K16: =J16*I16 -> 0.162
A17: {=_xlfn.IFS(H17, "Done", B17 > NOW(), "Not Released", C17 < NOW(), "Overdue", TRUE, ROUND(C17 - NOW(), 1) & " Days")} -> Done | B17: 45961 | C17: 45995 | D17: COMP1071 | E17: Computer Systems | F17: LMC Programming Assignment | G17: Coursework | H17: TRUE | I17: 0.79 | J17: 0.17 | K17: =J17*I17 -> 0.1343
A18: {=_xlfn.IFS(H18, "Done", B18 > NOW(), "Not Released", C18 < NOW(), "Overdue", TRUE, ROUND(C18 - NOW(), 1) & " Days")} -> Done | B18: 45968 | C18: 45975 | D18: COMP1071 | E18: Computer Systems | F18: Digital Electronics Benchtest | G18: Exam | H18: TRUE | I18: 0.875 | J18: 0.17 | K18: =J18*I18 -> 0.14875
H19: FALSE
H20: FALSE

Sheet Calculator
B2: Attended:
C3: Week 1 | D3: Week 2 | E3: Week 3 | F3: Week 4 | G3: Week 5 | H3: Week 6 | I3: Week 7 | J3: Week 8 | K3: Week 9 | L3: Week 10 | M3: Week 11 | N3: Week 12 | O3: Week 13 | P3: Week 14 | Q3: Week 15 | R3: Week 16 | S3: Week 17 | T3: Week 18 | U3: Week 19 | V3: Week 20 | W3: Week 21 | X3: Week 22 | Y3: Week 23 | Z3: Week 24 | AA3: Week 25 | AB3: Week 26 | AC3: Week 27 | AD3: Week 28 | AE3: Week 29 | AF3: Week 30 | AG3: Total:
B4: Monday | C4: =COUNTIFS('Attendence Tracker'!$A$2:$A$1002, $B4, 'Attendence Tracker'!F$2:F$1002, "Attended") -> 0 | D4: =COUNTIFS('Attendence Tracker'!$A$2:$A$1002, $B4, 'Attendence Tracker'!G$2:G$1002, "Attended") -> 4 | E4: =COUNTIFS('Attendence Tracker'!$A$2:$A$1002, $B4, 'Attendence Tracker'!H$2:H$1002, "Attended") -> 2 | F4: =COUNTIFS('Attendence Tracker'!$A$2:$A$1002, $B4, 'Attendence Tracker'!I$2:I$1002, "Attended") -> 0 | G4: =COUNTIFS('Attendence Tracker'!$A$2:$A$1002, $B4, 'Attendence Tracker'!J$2:J$1002, "Attended") -> 2 | H4: =COUNTIFS('Attendence Tracker'!$A$2:$A$1002, $B4, 'Attendence Tracker'!K$2:K$1002, "Attended") -> 2 | I4: =COUNTIFS('Attendence Tracker'!$A$2:$A$1002, $B4, 'Attendence Tracker'!L$2:L$1002, "Attended") -> 3 | J4: =COUNTIFS('Attendence Tracker'!$A$2:$A$1002, $B4, 'Attendence Tracker'!M$2:M$1002, "Attended") -> 0 | ... AF4: =COUNTIFS('Attendence Tracker'!$A$2:$A$1002, $B4, 'Attendence Tracker'!AI$2:AI$1002, "Attended") -> 0 | AG4: =SUM(C4:AF4) -> 29
B5: Tuesday | C5: =COUNTIFS('Attendence Tracker'!$A$2:$A$1002, $B5, 'Attendence Tracker'!F$2:F$1002, "Attended") -> 0 | D5: =COUNTIFS('Attendence Tracker'!$A$2:$A$1002, $B5, 'Attendence Tracker'!G$2:G$1002, "Attended") -> 3 | E5: =COUNTIFS('Attendence Tracker'!$A$2:$A$1002, $B5, 'Attendence Tracker'!H$2:H$1002, "Attended") -> 1 | F5: =COUNTIFS('Attendence Tracker'!$A$2:$A$1002, $B5, 'Attendence Tracker'!I$2:I$1002, "Attended") -> 0 | G5: =COUNTIFS('Attendence Tracker'!$A$2:$A$1002, $B5, 'Attendence Tracker'!J$2:J$1002, "Attended") -> 2 | H5: =COUNTIFS('Attendence Tracker'!$A$2:$A$1002, $B5, 'Attendence Tracker'!K$2:K$1002, "Attended") -> 1 | I5: =COUNTIFS('Attendence Tracker'!$A$2:$A$1002, $B5, 'Attendence Tracker'!L$2:L$1002, "Attended") -> 1 | J5: =COUNTIFS('Attendence Tracker'!$A$2:$A$1002, $B5, 'Attendence Tracker'!M$2:M$1002, "Attended") -> 1 | ... AF5: =COUNTIFS('Attendence Tracker'!$A$2:$A$1002, $B5, 'Attendence Tracker'!AI$2:AI$1002, "Attended") -> 0 | AG5: =SUM(C5:AF5) -> 23
B6: Wednesday | C6: =COUNTIFS('Attendence Tracker'!$A$2:$A$1002, $B6, 'Attendence Tracker'!F$2:F$1002, "Attended") -> 0 | D6: =COUNTIFS('Attendence Tracker'!$A$2:$A$1002, $B6, 'Attendence Tracker'!G$2:G$1002, "Attended") -> 0 | E6: =COUNTIFS('Attendence Tracker'!$A$2:$A$1002, $B6, 'Attendence Tracker'!H$2:H$1002, "Attended") -> 0 | F6: =COUNTIFS('Attendence Tracker'!$A$2:$A$1002, $B6, 'Attendence Tracker'!I$2:I$1002, "Attended") -> 1 | G6: =COUNTIFS('Attendence Tracker'!$A$2:$A$1002, $B6, 'Attendence Tracker'!J$2:J$1002, "Attended") -> 0 | H6: =COUNTIFS('Attendence Tracker'!$A$2:$A$1002, $B6, 'Attendence Tracker'!K$2:K$1002, "Attended") -> 0 | I6: =COUNTIFS('Attendence Tracker'!$A$2:$A$1002, $B6, 'Attendence Tracker'!L$2:L$1002, "Attended") -> 0 | J6: =COUNTIFS('Attendence Tracker'!$A$2:$A$1002, $B6, 'Attendence Tracker'!M$2:M$1002, "Attended") -> 0 | ... AF6: =COUNTIFS('Attendence Tracker'!$A$2:$A$1002, $B6, 'Attendence Tracker'!AI$2:AI$1002, "Attended") -> 0 | AG6: =SUM(C6:AF6) -> 3
B7: Thursday | C7: =COUNTIFS('Attendence Tracker'!$A$2:$A$1002, $B7, 'Attendence Tracker'!F$2:F$1002, "Attended") -> 2 | D7: =COUNTIFS('Attendence Tracker'!$A$2:$A$1002, $B7, 'Attendence Tracker'!G$2:G$1002, "Attended") -> 3 | E7: =COUNTIFS('Attendence Tracker'!$A$2:$A$1002, $B7, 'Attendence Tracker'!H$2:H$1002, "Attended") -> 1 | F7: =COUNTIFS('Attendence Tracker'!$A$2:$A$1002, $B7, 'Attendence Tracker'!I$2:I$1002, "Attended") -> 1 | G7: =COUNTIFS('Attendence Tracker'!$A$2:$A$1002, $B7, 'Attendence Tracker'!J$2:J$1002, "Attended") -> 1 | H7: =COUNTIFS('Attendence Tracker'!$A$2:$A$1002, $B7, 'Attendence Tracker'!K$2:K$1002, "Attended") -> 3 | I7: =COUNTIFS('Attendence Tracker'!$A$2:$A$1002, $B7, 'Attendence Tracker'!L$2:L$1002, "Attended") -> 0 | J7: =COUNTIFS('Attendence Tracker'!$A$2:$A$1002, $B7, 'Attendence Tracker'!M$2:M$1002, "Attended") -> 1 | ... AF7: =COUNTIFS('Attendence Tracker'!$A$2:$A$1002, $B7, 'Attendence Tracker'!AI$2:AI$1002, "Attended") -> 0 | AG7: =SUM(C7:AF7) -> 23
B8: Friday | C8: =COUNTIFS('Attendence Tracker'!$A$2:$A$1002, $B8, 'Attendence Tracker'!F$2:F$1002, "Attended") -> 0 | D8: =COUNTIFS('Attendence Tracker'!$A$2:$A$1002, $B8, 'Attendence Tracker'!G$2:G$1002, "Attended") -> 1 | E8: =COUNTIFS('Attendence Tracker'!$A$2:$A$1002, $B8, 'Attendence Tracker'!H$2:H$1002, "Attended") -> 0 | F8: =COUNTIFS('Attendence Tracker'!$A$2:$A$1002, $B8, 'Attendence Tracker'!I$2:I$1002, "Attended") -> 3 | G8: =COUNTIFS('Attendence Tracker'!$A$2:$A$1002, $B8, 'Attendence Tracker'!J$2:J$1002, "Attended") -> 2 | H8: =COUNTIFS('Attendence Tracker'!$A$2:$A$1002, $B8, 'Attendence Tracker'!K$2:K$1002, "Attended") -> 1 | I8: =COUNTIFS('Attendence Tracker'!$A$2:$A$1002, $B8, 'Attendence Tracker'!L$2:L$1002, "Attended") -> 0 | J8: =COUNTIFS('Attendence Tracker'!$A$2:$A$1002, $B8, 'Attendence Tracker'!M$2:M$1002, "Attended") -> 1 | ... AF8: =COUNTIFS('Attendence Tracker'!$A$2:$A$1002, $B8, 'Attendence Tracker'!AI$2:AI$1002, "Attended") -> 0 | AG8: =SUM(C8:AF8) -> 21
B9: Total: | C9: =SUM(C4:C8) -> 2 | D9: =SUM(D4:D8) -> 11 | E9: =SUM(E4:E8) -> 4 | F9: =SUM(F4:F8) -> 5 | G9: =SUM(G4:G8) -> 7 | H9: =SUM(H4:H8) -> 7 | I9: =SUM(I4:I8) -> 4 | J9: =SUM(J4:J8) -> 3 | ... AF9: =SUM(AF4:AF8) -> 0 | AG9: =SUM(C9:AF9) -> 99
B11: Possible:
C12: Week 1 | D12: Week 2 | E12: Week 3 | F12: Week 4 | G12: Week 5 | H12: Week 6 | I12: Week 7 | J12: Week 8 | K12: Week 9 | L12: Week 10 | M12: Week 11 | N12: Week 12 | O12: Week 13 | P12: Week 14 | Q12: Week 15 | R12: Week 16 | S12: Week 17 | T12: Week 18 | U12: Week 19 | V12: Week 20 | W12: Week 21 | X12: Week 22 | Y12: Week 23 | Z12: Week 24 | AA12: Week 25 | AB12: Week 26 | AC12: Week 27 | AD12: Week 28 | AE12: Week 29 | AF12: Week 30 | AG12: Total:
B13: Monday | C13: =COUNTIFS('Attendence Tracker'!$A$2:$A$1002, $B13, 'Attendence Tracker'!F$2:F$1002, "Attended") + + COUNTIFS('Attendence Tracker'!$A$2:$A$1002, $B13, 'Attendence Tracker'!F$2:F$1002, "Work Done") + COUNTIFS('Attendence Tracker'!$A$2:$A$1002, $B13, 'Attendence Tracker'!F$2:F$1002, "Missed") -> 2 | D13: =COUNTIFS('Attendence Tracker'!$A$2:$A$1002, $B13, 'Attendence Tracker'!G$2:G$1002, "Attended") + + COUNTIFS('Attendence Tracker'!$A$2:$A$1002, $B13, 'Attendence Tracker'!G$2:G$1002, "Work Done") + COUNTIFS('Attendence Tracker'!$A$2:$A$1002, $B13, 'Attendence Tracker'!G$2:G$1002, "Missed") -> 4 | E13: =COUNTIFS('Attendence Tracker'!$A$2:$A$1002, $B13, 'Attendence Tracker'!H$2:H$1002, "Attended") + + COUNTIFS('Attendence Tracker'!$A$2:$A$1002, $B13, 'Attendence Tracker'!H$2:H$1002, "Work Done") + COUNTIFS('Attendence Tracker'!$A$2:$A$1002, $B13, 'Attendence Tracker'!H$2:H$1002, "Missed") -> 4 | F13: =COUNTIFS('Attendence Tracker'!$A$2:$A$1002, $B13, 'Attendence Tracker'!I$2:I$1002, "Attended") + + COUNTIFS('Attendence Tracker'!$A$2:$A$1002, $B13, 'Attendence Tracker'!I$2:I$1002, "Work Done") + COUNTIFS('Attendence Tracker'!$A$2:$A$1002, $B13, 'Attendence Tracker'!I$2:I$1002, "Missed") -> 4 | G13: =COUNTIFS('Attendence Tracker'!$A$2:$A$1002, $B13, 'Attendence Tracker'!J$2:J$1002, "Attended") + + COUNTIFS('Attendence Tracker'!$A$2:$A$1002, $B13, 'Attendence Tracker'!J$2:J$1002, "Work Done") + COUNTIFS('Attendence Tracker'!$A$2:$A$1002, $B13, 'Attendence Tracker'!J$2:J$1002, "Missed") -> 4 | H13: =COUNTIFS('Attendence Tracker'!$A$2:$A$1002, $B13, 'Attendence Tracker'!K$2:K$1002, "Attended") + + COUNTIFS('Attendence Tracker'!$A$2:$A$1002, $B13, 'Attendence Tracker'!K$2:K$1002, "Work Done") + COUNTIFS('Attendence Tracker'!$A$2:$A$1002, $B13, 'Attendence Tracker'!K$2:K$1002, "Missed") -> 4 | I13: =COUNTIFS('Attendence Tracker'!$A$2:$A$1002, $B13, 'Attendence Tracker'!L$2:L$1002, "Attended") + + COUNTIFS('Attendence Tracker'!$A$2:$A$1002, $B13, 'Attendence Tracker'!L$2:L$1002, "Work Done") + COUNTIFS('Attendence Tracker'!$A$2:$A$1002, $B13, 'Attendence Tracker'!L$2:L$1002, "Missed") -> 4 | J13: =COUNTIFS('Attendence Tracker'!$A$2:$A$1002, $B13, 'Attendence Tracker'!M$2:M$1002, "Attended") + + COUNTIFS('Attendence Tracker'!$A$2:$A$1002, $B13, 'Attendence Tracker'!M$2:M$1002, "Work Done") + COUNTIFS('Attendence Tracker'!$A$2:$A$1002, $B13, 'Attendence Tracker'!M$2:M$1002, "Missed") -> 4 | ... AF13: =COUNTIFS('Attendence Tracker'!$A$2:$A$1002, $B13, 'Attendence Tracker'!AI$2:AI$1002, "Attended") + + COUNTIFS('Attendence Tracker'!$A$2:$A$1002, $B13, 'Attendence Tracker'!AI$2:AI$1002, "Work Done") + COUNTIFS('Attendence Tracker'!$A$2:$A$1002, $B13, 'Attendence Tracker'!AI$2:AI$1002, "Missed") -> 0 | AG13: =SUM(C13:AF13) -> 68
B14: Tuesday | C14: =COUNTIFS('Attendence Tracker'!$A$2:$A$1002, $B14, 'Attendence Tracker'!F$2:F$1002, "Attended") + + COUNTIFS('Attendence Tracker'!$A$2:$A$1002, $B14, 'Attendence Tracker'!F$2:F$1002, "Work Done") + COUNTIFS('Attendence Tracker'!$A$2:$A$1002, $B14, 'Attendence Tracker'!F$2:F$1002, "Missed") -> 2 | D14: =COUNTIFS('Attendence Tracker'!$A$2:$A$1002, $B14, 'Attendence Tracker'!G$2:G$1002, "Attended") + + COUNTIFS('Attendence Tracker'!$A$2:$A$1002, $B14, 'Attendence Tracker'!G$2:G$1002, "Work Done") + COUNTIFS('Attendence Tracker'!$A$2:$A$1002, $B14, 'Attendence Tracker'!G$2:G$1002, "Missed") -> 3 | E14: =COUNTIFS('Attendence Tracker'!$A$2:$A$1002, $B14, 'Attendence Tracker'!H$2:H$1002, "Attended") + + COUNTIFS('Attendence Tracker'!$A$2:$A$1002, $B14, 'Attendence Tracker'!H$2:H$1002, "Work Done") + COUNTIFS('Attendence Tracker'!$A$2:$A$1002, $B14, 'Attendence Tracker'!H$2:H$1002, "Missed") -> 3 | F14: =COUNTIFS('Attendence Tracker'!$A$2:$A$1002, $B14, 'Attendence Tracker'!I$2:I$1002, "Attended") + + COUNTIFS('Attendence Tracker'!$A$2:$A$1002, $B14, 'Attendence Tracker'!I$2:I$1002, "Work Done") + COUNTIFS('Attendence Tracker'!$A$2:$A$1002, $B14, 'Attendence Tracker'!I$2:I$1002, "Missed") -> 3 | G14: =COUNTIFS('Attendence Tracker'!$A$2:$A$1002, $B14, 'Attendence Tracker'!J$2:J$1002, "Attended") + + COUNTIFS('Attendence Tracker'!$A$2:$A$1002, $B14, 'Attendence Tracker'!J$2:J$1002, "Work Done") + COUNTIFS('Attendence Tracker'!$A$2:$A$1002, $B14, 'Attendence Tracker'!J$2:J$1002, "Missed") -> 3 | H14: =COUNTIFS('Attendence Tracker'!$A$2:$A$1002, $B14, 'Attendence Tracker'!K$2:K$1002, "Attended") + + COUNTIFS('Attendence Tracker'!$A$2:$A$1002, $B14, 'Attendence Tracker'!K$2:K$1002, "Work Done") + COUNTIFS('Attendence Tracker'!$A$2:$A$1002, $B14, 'Attendence Tracker'!K$2:K$1002, "Missed") -> 3 | I14: =COUNTIFS('Attendence Tracker'!$A$2:$A$1002, $B14, 'Attendence Tracker'!L$2:L$1002, "Attended") + + COUNTIFS('Attendence Tracker'!$A$2:$A$1002, $B14, 'Attendence Tracker'!L$2:L$1002, "Work Done") + COUNTIFS('Attendence Tracker'!$A$2:$A$1002, $B14, 'Attendence Tracker'!L$2:L$1002, "Missed") -> 3 | J14: =COUNTIFS('Attendence Tracker'!$A$2:$A$1002, $B14, 'Attendence Tracker'!M$2:M$1002, "Attended") + + COUNTIFS('Attendence Tracker'!$A$2:$A$1002, $B14, 'Attendence Tracker'!M$2:M$1002, "Work Done") + COUNTIFS('Attendence Tracker'!$A$2:$A$1002, $B14, 'Attendence Tracker'!M$2:M$1002, "Missed") -> 3 | ... AF14: =COUNTIFS('Attendence Tracker'!$A$2:$A$1002, $B14, 'Attendence Tracker'!AI$2:AI$1002, "Attended") + + COUNTIFS('Attendence Tracker'!$A$2:$A$1002, $B14, 'Attendence Tracker'!AI$2:AI$1002, "Work Done") + COUNTIFS('Attendence Tracker'!$A$2:$A$1002, $B14, 'Attendence Tracker'!AI$2:AI$1002, "Missed") -> 0 | AG14: =SUM(C14:AF14) -> 52
B15: Wednesday | C15: =COUNTIFS('Attendence Tracker'!$A$2:$A$1002, $B15, 'Attendence Tracker'!F$2:F$1002, "Attended") + + COUNTIFS('Attendence Tracker'!$A$2:$A$1002, $B15, 'Attendence Tracker'!F$2:F$1002, "Work Done") + COUNTIFS('Attendence Tracker'!$A$2:$A$1002, $B15, 'Attendence Tracker'!F$2:F$1002, "Missed") -> 2 | D15: =COUNTIFS('Attendence Tracker'!$A$2:$A$1002, $B15, 'Attendence Tracker'!G$2:G$1002, "Attended") + + COUNTIFS('Attendence Tracker'!$A$2:$A$1002, $B15, 'Attendence Tracker'!G$2:G$1002, "Work Done") + COUNTIFS('Attendence Tracker'!$A$2:$A$1002, $B15, 'Attendence Tracker'!G$2:G$1002, "Missed") -> 2 | E15: =COUNTIFS('Attendence Tracker'!$A$2:$A$1002, $B15, 'Attendence Tracker'!H$2:H$1002, "Attended") + + COUNTIFS('Attendence Tracker'!$A$2:$A$1002, $B15, 'Attendence Tracker'!H$2:H$1002, "Work Done") + COUNTIFS('Attendence Tracker'!$A$2:$A$1002, $B15, 'Attendence Tracker'!H$2:H$1002, "Missed") -> 2 | F15: =COUNTIFS('Attendence Tracker'!$A$2:$A$1002, $B15, 'Attendence Tracker'!I$2:I$1002, "Attended") + + COUNTIFS('Attendence Tracker'!$A$2:$A$1002, $B15, 'Attendence Tracker'!I$2:I$1002, "Work Done") + COUNTIFS('Attendence Tracker'!$A$2:$A$1002, $B15, 'Attendence Tracker'!I$2:I$1002, "Missed") -> 2 | G15: =COUNTIFS('Attendence Tracker'!$A$2:$A$1002, $B15, 'Attendence Tracker'!J$2:J$1002, "Attended") + + COUNTIFS('Attendence Tracker'!$A$2:$A$1002, $B15, 'Attendence Tracker'!J$2:J$1002, "Work Done") + COUNTIFS('Attendence Tracker'!$A$2:$A$1002, $B15, 'Attendence Tracker'!J$2:J$1002, "Missed") -> 2 | H15: =COUNTIFS('Attendence Tracker'!$A$2:$A$1002, $B15, 'Attendence Tracker'!K$2:K$1002, "Attended") + + COUNTIFS('Attendence Tracker'!$A$2:$A$1002, $B15, 'Attendence Tracker'!K$2:K$1002, "Work Done") + COUNTIFS('Attendence Tracker'!$A$2:$A$1002, $B15, 'Attendence Tracker'!K$2:K$1002, "Missed") -> 2 | I15: =COUNTIFS('Attendence Tracker'!$A$2:$A$1002, $B15, 'Attendence Tracker'!L$2:L$1002, "Attended") + + COUNTIFS('Attendence Tracker'!$A$2:$A$1002, $B15, 'Attendence Tracker'!L$2:L$1002, "Work Done") + COUNTIFS('Attendence Tracker'!$A$2:$A$1002, $B15, 'Attendence Tracker'!L$2:L$1002, "Missed") -> 1 | J15: =COUNTIFS('Attendence Tracker'!$A$2:$A$1002, $B15, 'Attendence Tracker'!M$2:M$1002, "Attended") + + COUNTIFS('Attendence Tracker'!$A$2:$A$1002, $B15, 'Attendence Tracker'!M$2:M$1002, "Work Done") + COUNTIFS('Attendence Tracker'!$A$2:$A$1002, $B15, 'Attendence Tracker'!M$2:M$1002, "Missed") -> 2 | ... AF15: =COUNTIFS('Attendence Tracker'!$A$2:$A$1002, $B15, 'Attendence Tracker'!AI$2:AI$1002, "Attended") + + COUNTIFS('Attendence Tracker'!$A$2:$A$1002, $B15, 'Attendence Tracker'!AI$2:AI$1002, "Work Done") + COUNTIFS('Attendence Tracker'!$A$2:$A$1002, $B15, 'Attendence Tracker'!AI$2:AI$1002, "Missed") -> 0 | AG15: =SUM(C15:AF15) -> 40
B16: Thursday | C16: =COUNTIFS('Attendence Tracker'!$A$2:$A$1002, $B16, 'Attendence Tracker'!F$2:F$1002, "Attended") + + COUNTIFS('Attendence Tracker'!$A$2:$A$1002, $B16, 'Attendence Tracker'!F$2:F$1002, "Work Done") + COUNTIFS('Attendence Tracker'!$A$2:$A$1002, $B16, 'Attendence Tracker'!F$2:F$1002, "Missed") -> 3 | D16: =COUNTIFS('Attendence Tracker'!$A$2:$A$1002, $B16, 'Attendence Tracker'!G$2:G$1002, "Attended") + + COUNTIFS('Attendence Tracker'!$A$2:$A$1002, $B16, 'Attendence Tracker'!G$2:G$1002, "Work Done") + COUNTIFS('Attendence Tracker'!$A$2:$A$1002, $B16, 'Attendence Tracker'!G$2:G$1002, "Missed") -> 4 | E16: =COUNTIFS('Attendence Tracker'!$A$2:$A$1002, $B16, 'Attendence Tracker'!H$2:H$1002, "Attended") + + COUNTIFS('Attendence Tracker'!$A$2:$A$1002, $B16, 'Attendence Tracker'!H$2:H$1002, "Work Done") + COUNTIFS('Attendence Tracker'!$A$2:$A$1002, $B16, 'Attendence Tracker'!H$2:H$1002, "Missed") -> 4 | F16: =COUNTIFS('Attendence Tracker'!$A$2:$A$1002, $B16, 'Attendence Tracker'!I$2:I$1002, "Attended") + + COUNTIFS('Attendence Tracker'!$A$2:$A$1002, $B16, 'Attendence Tracker'!I$2:I$1002, "Work Done") + COUNTIFS('Attendence Tracker'!$A$2:$A$1002, $B16, 'Attendence Tracker'!I$2:I$1002, "Missed") -> 4 | G16: =COUNTIFS('Attendence Tracker'!$A$2:$A$1002, $B16, 'Attendence Tracker'!J$2:J$1002, "Attended") + + COUNTIFS('Attendence Tracker'!$A$2:$A$1002, $B16, 'Attendence Tracker'!J$2:J$1002, "Work Done") + COUNTIFS('Attendence Tracker'!$A$2:$A$1002, $B16, 'Attendence Tracker'!J$2:J$1002, "Missed") -> 4 | H16: =COUNTIFS('Attendence Tracker'!$A$2:$A$1002, $B16, 'Attendence Tracker'!K$2:K$1002, "Attended") + + COUNTIFS('Attendence Tracker'!$A$2:$A$1002, $B16, 'Attendence Tracker'!K$2:K$1002, "Work Done") + COUNTIFS('Attendence Tracker'!$A$2:$A$1002, $B16, 'Attendence Tracker'!K$2:K$1002, "Missed") -> 4 | I16: =COUNTIFS('Attendence Tracker'!$A$2:$A$1002, $B16, 'Attendence Tracker'!L$2:L$1002, "Attended") + + COUNTIFS('Attendence Tracker'!$A$2:$A$1002, $B16, 'Attendence Tracker'!L$2:L$1002, "Work Done") + COUNTIFS('Attendence Tracker'!$A$2:$A$1002, $B16, 'Attendence Tracker'!L$2:L$1002, "Missed") -> 4 | J16: =COUNTIFS('Attendence Tracker'!$A$2:$A$1002, $B16, 'Attendence Tracker'!M$2:M$1002, "Attended") + + COUNTIFS('Attendence Tracker'!$A$2:$A$1002, $B16, 'Attendence Tracker'!M$2:M$1002, "Work Done") + COUNTIFS('Attendence Tracker'!$A$2:$A$1002, $B16, 'Attendence Tracker'!M$2:M$1002, "Missed") -> 4 | ... AF16: =COUNTIFS('Attendence Tracker'!$A$2:$A$1002, $B16, 'Attendence Tracker'!AI$2:AI$1002, "Attended") + + COUNTIFS('Attendence Tracker'!$A$2:$A$1002, $B16, 'Attendence Tracker'!AI$2:AI$1002, "Work Done") + COUNTIFS('Attendence Tracker'!$A$2:$A$1002, $B16, 'Attendence Tracker'!AI$2:AI$1002, "Missed") -> 0 | AG16: =SUM(C16:AF16) -> 70
B17: Friday | C17: =COUNTIFS('Attendence Tracker'!$A$2:$A$1002, $B17, 'Attendence Tracker'!F$2:F$1002, "Attended") + + COUNTIFS('Attendence Tracker'!$A$2:$A$1002, $B17, 'Attendence Tracker'!F$2:F$1002, "Work Done") + COUNTIFS('Attendence Tracker'!$A$2:$A$1002, $B17, 'Attendence Tracker'!F$2:F$1002, "Missed") -> 2 | D17: =COUNTIFS('Attendence Tracker'!$A$2:$A$1002, $B17, 'Attendence Tracker'!G$2:G$1002, "Attended") + + COUNTIFS('Attendence Tracker'!$A$2:$A$1002, $B17, 'Attendence Tracker'!G$2:G$1002, "Work Done") + COUNTIFS('Attendence Tracker'!$A$2:$A$1002, $B17, 'Attendence Tracker'!G$2:G$1002, "Missed") -> 3 | E17: =COUNTIFS('Attendence Tracker'!$A$2:$A$1002, $B17, 'Attendence Tracker'!H$2:H$1002, "Attended") + + COUNTIFS('Attendence Tracker'!$A$2:$A$1002, $B17, 'Attendence Tracker'!H$2:H$1002, "Work Done") + COUNTIFS('Attendence Tracker'!$A$2:$A$1002, $B17, 'Attendence Tracker'!H$2:H$1002, "Missed") -> 4 | F17: =COUNTIFS('Attendence Tracker'!$A$2:$A$1002, $B17, 'Attendence Tracker'!I$2:I$1002, "Attended") + + COUNTIFS('Attendence Tracker'!$A$2:$A$1002, $B17, 'Attendence Tracker'!I$2:I$1002, "Work Done") + COUNTIFS('Attendence Tracker'!$A$2:$A$1002, $B17, 'Attendence Tracker'!I$2:I$1002, "Missed") -> 3 | G17: =COUNTIFS('Attendence Tracker'!$A$2:$A$1002, $B17, 'Attendence Tracker'!J$2:J$1002, "Attended") + + COUNTIFS('Attendence Tracker'!$A$2:$A$1002, $B17, 'Attendence Tracker'!J$2:J$1002, "Work Done") + COUNTIFS('Attendence Tracker'!$A$2:$A$1002, $B17, 'Attendence Tracker'!J$2:J$1002, "Missed") -> 3 | H17: =COUNTIFS('Attendence Tracker'!$A$2:$A$1002, $B17, 'Attendence Tracker'!K$2:K$1002, "Attended") + + COUNTIFS('Attendence Tracker'!$A$2:$A$1002, $B17, 'Attendence Tracker'!K$2:K$1002, "Work Done") + COUNTIFS('Attendence Tracker'!$A$2:$A$1002, $B17, 'Attendence Tracker'!K$2:K$1002, "Missed") -> 2 | I17: =COUNTIFS('Attendence Tracker'!$A$2:$A$1002, $B17, 'Attendence Tracker'!L$2:L$1002, "Attended") + + COUNTIFS('Attendence Tracker'!$A$2:$A$1002, $B17, 'Attendence Tracker'!L$2:L$1002, "Work Done") + COUNTIFS('Attendence Tracker'!$A$2:$A$1002, $B17, 'Attendence Tracker'!L$2:L$1002, "Missed") -> 4 | J17: =COUNTIFS('Attendence Tracker'!$A$2:$A$1002, $B17, 'Attendence Tracker'!M$2:M$1002, "Attended") + + COUNTIFS('Attendence Tracker'!$A$2:$A$1002, $B17, 'Attendence Tracker'!M$2:M$1002, "Work Done") + COUNTIFS('Attendence Tracker'!$A$2:$A$1002, $B17, 'Attendence Tracker'!M$2:M$1002, "Missed") -> 2 | ... AF17: =COUNTIFS('Attendence Tracker'!$A$2:$A$1002, $B17, 'Attendence Tracker'!AI$2:AI$1002, "Attended") + + COUNTIFS('Attendence Tracker'!$A$2:$A$1002, $B17, 'Attendence Tracker'!AI$2:AI$1002, "Work Done") + COUNTIFS('Attendence Tracker'!$A$2:$A$1002, $B17, 'Attendence Tracker'!AI$2:AI$1002, "Missed") -> 0 | AG17: =SUM(C17:AF17) -> 57
B18: Total: | C18: =SUM(C13:C17) -> 11 | D18: =SUM(D13:D17) -> 16 | E18: =SUM(E13:E17) -> 17 | F18: =SUM(F13:F17) -> 16 | G18: =SUM(G13:G17) -> 16 | H18: =SUM(H13:H17) -> 15 | I18: =SUM(I13:I17) -> 16 | J18: =SUM(J13:J17) -> 15 | ... AF18: =SUM(AF13:AF17) -> 0 | AG18: =SUM(C18:AF18) -> 287
B20: Percentage:
C21: Week 1 | D21: Week 2 | E21: Week 3 | F21: Week 4 | G21: Week 5 | H21: Week 6 | I21: Week 7 | J21: Week 8 | K21: Week 9 | L21: Week 10 | M21: Week 11 | N21: Week 12 | O21: Week 13 | P21: Week 14 | Q21: Week 15 | R21: Week 16 | S21: Week 17 | T21: Week 18 | U21: Week 19 | V21: Week 20 | W21: Week 21 | X21: Week 22 | Y21: Week 23 | Z21: Week 24 | AA21: Week 25 | AB21: Week 26 | AC21: Week 27 | AD21: Week 28 | AE21: Week 29 | AF21: Week 30 | AG21: Daily Average:
B22: Monday | C22: =IF(C13=0, 0, C4/C13) -> 0 | D22: =IF(D13=0, 0, D4/D13) -> 1 | E22: =IF(E13=0, 0, E4/E13) -> 0.5 | F22: =IF(F13=0, 0, F4/F13) -> 0 | G22: =IF(G13=0, 0, G4/G13) -> 0.5 | H22: =IF(H13=0, 0, H4/H13) -> 0.5 | I22: =IF(I13=0, 0, I4/I13) -> 0.75 | J22: =IF(J13=0, 0, J4/J13) -> 0 | ... AF22: =IF(AF13=0, 0, AF4/AF13) -> 0 | AG22: =AG4/AG13 -> 0.42647059
B23: Tuesday | C23: =IF(C14=0, 0, C5/C14) -> 0 | D23: =IF(D14=0, 0, D5/D14) -> 1 | E23: =IF(E14=0, 0, E5/E14) -> 0.33333333 | F23: =IF(F14=0, 0, F5/F14) -> 0 | G23: =IF(G14=0, 0, G5/G14) -> 0.66666667 | H23: =IF(H14=0, 0, H5/H14) -> 0.33333333 | I23: =IF(I14=0, 0, I5/I14) -> 0.33333333 | J23: =IF(J14=0, 0, J5/J14) -> 0.33333333 | ... AF23: =IF(AF14=0, 0, AF5/AF14) -> 0 | AG23: =AG5/AG14 -> 0.44230769
B24: Wednesday | C24: =IF(C15=0, 0, C6/C15) -> 0 | D24: =IF(D15=0, 0, D6/D15) -> 0 | E24: =IF(E15=0, 0, E6/E15) -> 0 | F24: =IF(F15=0, 0, F6/F15) -> 0.5 | G24: =IF(G15=0, 0, G6/G15) -> 0 | H24: =IF(H15=0, 0, H6/H15) -> 0 | I24: =IF(I15=0, 0, I6/I15) -> 0 | J24: =IF(J15=0, 0, J6/J15) -> 0 | ... AF24: =IF(AF15=0, 0, AF6/AF15) -> 0 | AG24: =AG6/AG15 -> 0.075
B25: Thursday | C25: =IF(C16=0, 0, C7/C16) -> 0.66666667 | D25: =IF(D16=0, 0, D7/D16) -> 0.75 | E25: =IF(E16=0, 0, E7/E16) -> 0.25 | F25: =IF(F16=0, 0, F7/F16) -> 0.25 | G25: =IF(G16=0, 0, G7/G16) -> 0.25 | H25: =IF(H16=0, 0, H7/H16) -> 0.75 | I25: =IF(I16=0, 0, I7/I16) -> 0 | J25: =IF(J16=0, 0, J7/J16) -> 0.25 | ... AF25: =IF(AF16=0, 0, AF7/AF16) -> 0 | AG25: =AG7/AG16 -> 0.32857143
B26: Friday | C26: =IF(C17=0, 0, C8/C17) -> 0 | D26: =IF(D17=0, 0, D8/D17) -> 0.33333333 | E26: =IF(E17=0, 0, E8/E17) -> 0 | F26: =IF(F17=0, 0, F8/F17) -> 1 | G26: =IF(G17=0, 0, G8/G17) -> 0.66666667 | H26: =IF(H17=0, 0, H8/H17) -> 0.5 | I26: =IF(I17=0, 0, I8/I17) -> 0 | J26: =IF(J17=0, 0, J8/J17) -> 0.5 | ... AF26: =IF(AF17=0, 0, AF8/AF17) -> 0 | AG26: =AG8/AG17 -> 0.36842105
B27: Weekly Average: | C27: =C9/C18 -> 0.18181818 | D27: =D9/D18 -> 0.6875 | E27: =E9/E18 -> 0.23529412 | F27: =F9/F18 -> 0.3125 | G27: =G9/G18 -> 0.4375 | H27: =H9/H18 -> 0.46666667 | I27: =I9/I18 -> 0.25 | J27: =J9/J18 -> 0.2 | ... AG27: =AG9/AG18 -> 0.34494774
B29: Formatives: | J29: Summatives:
C30: Total | D30: Done | E30: Not Released | F30: To-Do | G30: All | H30: Average Score | K30: Total | L30: Done | M30: Not Released | N30: To-Do | O30: All | P30: Average Score
B31: Algorithms and Data Structures | C31: =COUNTIF('Formatives Tracker'!$E$2:$E$1008, $B31) -> 0 | D31: =COUNTIFS('Formatives Tracker'!$E$2:$E$1008, $B31, 'Formatives Tracker'!$A$2:$A$1008, "Done") -> 0 | E31: =COUNTIFS('Formatives Tracker'!$E$2:$E$1008, $B31, 'Formatives Tracker'!$A$2:$A$1008, "Not Released") -> 0 | F31: =C31-D31-E31 -> 0 | G31: =C31-D31 -> 0 | H31: =IFERROR(AVERAGEIF('Formatives Tracker'!$E$2:$E$1008, $B31, 'Formatives Tracker'!$J$2:$J$1008), 0) -> 0 | J31: Algorithms and Data Structures | K31: =COUNTIF('Summatives Tracker'!$E$2:$E$1004, $J31) -> 2 | L31: =COUNTIFS('Summatives Tracker'!$E$2:$E$1004, $B31, 'Summatives Tracker'!$A$2:$A$1004, "Done") -> 2 | M31: =COUNTIFS('Summatives Tracker'!$E$2:$E$1004, $B31, 'Summatives Tracker'!$A$2:$A$1004, "Not Released") -> 0 | N31: =K31-L31-M31 -> 0 | O31: =K31-L31 -> 0 | P31: =IFERROR(AVERAGEIF('Summatives Tracker'!$E$6:$E$1004, $B31, 'Summatives Tracker'!$I$6:$I$1004), 0) -> 0.75
B32: Computational Thinking | C32: =COUNTIF('Formatives Tracker'!$E$2:$E$1008, $B32) -> 0 | D32: =COUNTIFS('Formatives Tracker'!$E$2:$E$1008, $B32, 'Formatives Tracker'!$A$2:$A$1008, "Done") -> 0 | E32: =COUNTIFS('Formatives Tracker'!$E$2:$E$1008, $B32, 'Formatives Tracker'!$A$2:$A$1008, "Not Released") -> 0 | F32: =C32-D32-E32 -> 0 | G32: =C32-D32 -> 0 | H32: =IFERROR(AVERAGEIF('Formatives Tracker'!$E$2:$E$1008, $B32, 'Formatives Tracker'!$J$2:$J$1008), 0) -> 0 | J32: Computational Thinking | K32: =COUNTIF('Summatives Tracker'!$E$2:$E$1004, $J32) -> 4 | L32: =COUNTIFS('Summatives Tracker'!$E$2:$E$1004, $B32, 'Summatives Tracker'!$A$2:$A$1004, "Done") -> 4 | M32: =COUNTIFS('Summatives Tracker'!$E$2:$E$1004, $B32, 'Summatives Tracker'!$A$2:$A$1004, "Not Released") -> 0 | N32: =K32-L32-M32 -> 0 | O32: =K32-L32 -> 0 | P32: =IFERROR(AVERAGEIF('Summatives Tracker'!$E$6:$E$1004, $B32, 'Summatives Tracker'!$I$6:$I$1004), 0) -> 0.72578877
B33: Computer Systems | C33: =COUNTIF('Formatives Tracker'!$E$2:$E$1008, $B33) -> 0 | D33: =COUNTIFS('Formatives Tracker'!$E$2:$E$1008, $B33, 'Formatives Tracker'!$A$2:$A$1008, "Done") -> 0 | E33: =COUNTIFS('Formatives Tracker'!$E$2:$E$1008, $B33, 'Formatives Tracker'!$A$2:$A$1008, "Not Released") -> 0 | F33: =C33-D33-E33 -> 0 | G33: =C33-D33 -> 0 | H33: =IFERROR(AVERAGEIF('Formatives Tracker'!$E$2:$E$1008, $B33, 'Formatives Tracker'!$J$2:$J$1008), 0) -> 0 | J33: Computer Systems | K33: =COUNTIF('Summatives Tracker'!$E$2:$E$1004, $J33) -> 3 | L33: =COUNTIFS('Summatives Tracker'!$E$2:$E$1004, $B33, 'Summatives Tracker'!$A$2:$A$1004, "Done") -> 3 | M33: =COUNTIFS('Summatives Tracker'!$E$2:$E$1004, $B33, 'Summatives Tracker'!$A$2:$A$1004, "Not Released") -> 0 | N33: =K33-L33-M33 -> 0 | O33: =K33-L33 -> 0 | P33: =IFERROR(AVERAGEIF('Summatives Tracker'!$E$6:$E$1004, $B33, 'Summatives Tracker'!$I$6:$I$1004), 0) -> 0.8325
B34: Discrete Mathematics | C34: =COUNTIF('Formatives Tracker'!$E$2:$E$1008, $B34) -> 12 | D34: =COUNTIFS('Formatives Tracker'!$E$2:$E$1008, $B34, 'Formatives Tracker'!$A$2:$A$1008, "Done") -> 12 | E34: =COUNTIFS('Formatives Tracker'!$E$2:$E$1008, $B34, 'Formatives Tracker'!$A$2:$A$1008, "Not Released") -> 0 | F34: =C34-D34-E34 -> 0 | G34: =C34-D34 -> 0 | H34: =IFERROR(AVERAGEIF('Formatives Tracker'!$E$2:$E$1008, $B34, 'Formatives Tracker'!$J$2:$J$1008), 0) -> 0.785 | J34: Discrete Mathematics | K34: =COUNTIF('Summatives Tracker'!$E$2:$E$1004, $J34) -> 3 | L34: =COUNTIFS('Summatives Tracker'!$E$2:$E$1004, $B34, 'Summatives Tracker'!$A$2:$A$1004, "Done") -> 3 | M34: =COUNTIFS('Summatives Tracker'!$E$2:$E$1004, $B34, 'Summatives Tracker'!$A$2:$A$1004, "Not Released") -> 0 | N34: =K34-L34-M34 -> 0 | O34: =K34-L34 -> 0 | P34: =IFERROR(AVERAGEIF('Summatives Tracker'!$E$6:$E$1004, $B34, 'Summatives Tracker'!$I$6:$I$1004), 0) -> 0.55
B35: Mathematics for Computer Science | C35: =COUNTIF('Formatives Tracker'!$E$2:$E$1008, $B35) -> 15 | D35: =COUNTIFS('Formatives Tracker'!$E$2:$E$1008, $B35, 'Formatives Tracker'!$A$2:$A$1008, "Done") -> 15 | E35: =COUNTIFS('Formatives Tracker'!$E$2:$E$1008, $B35, 'Formatives Tracker'!$A$2:$A$1008, "Not Released") -> 0 | F35: =C35-D35-E35 -> 0 | G35: =C35-D35 -> 0 | H35: =IFERROR(AVERAGEIF('Formatives Tracker'!$E$2:$E$1008, $B35, 'Formatives Tracker'!$J$2:$J$1008), 0) -> 0.80560374 | J35: Mathematics for Computer Science | K35: =COUNTIF('Summatives Tracker'!$E$2:$E$1004, $J35) -> 2 | L35: =COUNTIFS('Summatives Tracker'!$E$2:$E$1004, $B35, 'Summatives Tracker'!$A$2:$A$1004, "Done") -> 2 | M35: =COUNTIFS('Summatives Tracker'!$E$2:$E$1004, $B35, 'Summatives Tracker'!$A$2:$A$1004, "Not Released") -> 0 | N35: =K35-L35-M35 -> 0 | O35: =K35-L35 -> 0 | P35: =IFERROR(AVERAGEIF('Summatives Tracker'!$E$6:$E$1004, $B35, 'Summatives Tracker'!$I$6:$I$1004), 0) -> 0.725
B36: Programming (Black) | C36: =COUNTIF('Formatives Tracker'!$E$2:$E$1008, $B36) -> 0 | D36: =COUNTIFS('Formatives Tracker'!$E$2:$E$1008, $B36, 'Formatives Tracker'!$A$2:$A$1008, "Done") -> 0 | E36: =COUNTIFS('Formatives Tracker'!$E$2:$E$1008, $B36, 'Formatives Tracker'!$A$2:$A$1008, "Not Released") -> 0 | F36: =C36-D36-E36 -> 0 | G36: =C36-D36 -> 0 | H36: =IFERROR(AVERAGEIF('Formatives Tracker'!$E$2:$E$1008, $B36, 'Formatives Tracker'!$J$2:$J$1008), 0) -> 0 | J36: Programming (Black) | K36: =COUNTIF('Summatives Tracker'!$E$2:$E$1004, $J36) -> 3 | L36: =COUNTIFS('Summatives Tracker'!$E$2:$E$1004, $B36, 'Summatives Tracker'!$A$2:$A$1004, "Done") -> 3 | M36: =COUNTIFS('Summatives Tracker'!$E$2:$E$1004, $B36, 'Summatives Tracker'!$A$2:$A$1004, "Not Released") -> 0 | N36: =K36-L36-M36 -> 0 | O36: =K36-L36 -> 0 | P36: =IFERROR(AVERAGEIF('Summatives Tracker'!$E$6:$E$1004, $B36, 'Summatives Tracker'!$I$6:$I$1004), 0) -> 0.79333333
B38: Modules:
C39: Achieved Marks | D39: Possible Marks | E39: Remaining Possible Marks | F39: 1st Required | G39: 2:1 Required | H39: 2:2 Required | I39: Pass Required
B40: Algorithms and Data Structures | C40: =IFERROR(SUMIF('Summatives Tracker'!$E$2:$E$1004, $B40, 'Summatives Tracker'!$K$2:$K$1004), 0) -> 0.255 | D40: =SUMIFS('Summatives Tracker'!$J$2:$J$1003, 'Summatives Tracker'!$I$2:$I$1003, ">0", 'Summatives Tracker'!$E$2:$E$1003, B40) -> 0.34 | E40: =1-D40 -> 0.66 | F40: =IFERROR(IF((0.7-$C40)/$E40>=0,(0.7-$C40)/$E40,0), IF($C40>=0.7, 0, 1)) -> 0.67424242 | G40: =IFERROR(IF((0.6-$C40)/$E40>=0,(0.6-$C40)/$E40,0), IF($C40>=0.6, 0, 1)) -> 0.52272727 | H40: =IFERROR(IF((0.5-$C40)/$E40>=0,(0.5-$C40)/$E40,0), IF($C40>=0.5, 0, 1)) -> 0.37121212 | I40: =IFERROR(IF((0.4-$C40)/$E40>=0,(0.4-$C40)/$E40,0), IF($C40>=0.4, 0, 1)) -> 0.21969697
B41: Computational Thinking | C41: =IFERROR(SUMIF('Summatives Tracker'!$E$2:$E$1004, $B41, 'Summatives Tracker'!$K$2:$K$1004), 0) -> 0.71405704 | D41: =SUMIFS('Summatives Tracker'!$J$2:$J$1003, 'Summatives Tracker'!$I$2:$I$1003, ">0", 'Summatives Tracker'!$E$2:$E$1003, B41) -> 1 | E41: =1-D41 -> 0 | F41: =IFERROR(IF((0.7-$C41)/$E41>=0,(0.7-$C41)/$E41,0), IF($C41>=0.7, 0, 1)) -> 0 | G41: =IFERROR(IF((0.6-$C41)/$E41>=0,(0.6-$C41)/$E41,0), IF($C41>=0.6, 0, 1)) -> 0 | H41: =IFERROR(IF((0.5-$C41)/$E41>=0,(0.5-$C41)/$E41,0), IF($C41>=0.5, 0, 1)) -> 0 | I41: =IFERROR(IF((0.4-$C41)/$E41>=0,(0.4-$C41)/$E41,0), IF($C41>=0.4, 0, 1)) -> 0
B42: Computer Systems | C42: =IFERROR(SUMIF('Summatives Tracker'!$E$2:$E$1004, $B42, 'Summatives Tracker'!$K$2:$K$1004), 0) -> 0.60315 | D42: =SUMIFS('Summatives Tracker'!$J$2:$J$1003, 'Summatives Tracker'!$I$2:$I$1003, ">0", 'Summatives Tracker'!$E$2:$E$1003, B42) -> 1 | E42: =1-D42 -> 0 | F42: =IFERROR(IF((0.7-$C42)/$E42>=0,(0.7-$C42)/$E42,0), IF($C42>=0.7, 0, 1)) -> 1 | G42: =IFERROR(IF((0.6-$C42)/$E42>=0,(0.6-$C42)/$E42,0), IF($C42>=0.6, 0, 1)) -> 0 | H42: =IFERROR(IF((0.5-$C42)/$E42>=0,(0.5-$C42)/$E42,0), IF($C42>=0.5, 0, 1)) -> 0 | I42: =IFERROR(IF((0.4-$C42)/$E42>=0,(0.4-$C42)/$E42,0), IF($C42>=0.4, 0, 1)) -> 0
B43: Discrete Mathematics | C43: =IFERROR(SUMIF('Summatives Tracker'!$E$2:$E$1004, $B43, 'Summatives Tracker'!$K$2:$K$1004), 0) -> 0.55 | D43: =SUMIFS('Summatives Tracker'!$J$2:$J$1003, 'Summatives Tracker'!$I$2:$I$1003, ">0", 'Summatives Tracker'!$E$2:$E$1003, B43) -> 1 | E43: =1-D43 -> 0 | F43: =IFERROR(IF((0.7-$C43)/$E43>=0,(0.7-$C43)/$E43,0), IF($C43>=0.7, 0, 1)) -> 1 | G43: =IFERROR(IF((0.6-$C43)/$E43>=0,(0.6-$C43)/$E43,0), IF($C43>=0.6, 0, 1)) -> 1 | H43: =IFERROR(IF((0.5-$C43)/$E43>=0,(0.5-$C43)/$E43,0), IF($C43>=0.5, 0, 1)) -> 0 | I43: =IFERROR(IF((0.4-$C43)/$E43>=0,(0.4-$C43)/$E43,0), IF($C43>=0.4, 0, 1)) -> 0
B44: Mathematics for Computer Science | C44: =IFERROR(SUMIF('Summatives Tracker'!$E$2:$E$1004, $B44, 'Summatives Tracker'!$K$2:$K$1004), 0) -> 0.6029 | D44: =SUMIFS('Summatives Tracker'!$J$2:$J$1003, 'Summatives Tracker'!$I$2:$I$1003, ">0", 'Summatives Tracker'!$E$2:$E$1003, B44) -> 1 | E44: =1-D44 -> 0 | F44: =IFERROR(IF((0.7-$C44)/$E44>=0,(0.7-$C44)/$E44,0), IF($C44>=0.7, 0, 1)) -> 1 | G44: =IFERROR(IF((0.6-$C44)/$E44>=0,(0.6-$C44)/$E44,0), IF($C44>=0.6, 0, 1)) -> 0 | H44: =IFERROR(IF((0.5-$C44)/$E44>=0,(0.5-$C44)/$E44,0), IF($C44>=0.5, 0, 1)) -> 0 | I44: =IFERROR(IF((0.4-$C44)/$E44>=0,(0.4-$C44)/$E44,0), IF($C44>=0.4, 0, 1)) -> 0
